<?xml version="1.0" ?>
<mujoco>
<asset>
    <texture name="grid" type="2d" builtin="checker" width="512" height="512" rgb1=".1 .2 .3" rgb2=".2 .3 .4"/>
    <material name="grid" texture="grid" texrepeat="1 1" texuniform="true" reflectance=".2"/>
    <mesh name="chasis" scale=".1 .06 .015"
      vertex=" 9   2   0
              -10  10  10
               9  -2   0
               10  3  -10
               10 -3  -10
              -8   10 -10
              -10 -10  10
              -8  -10 -10
              -5   0   20"/>
  </asset>
    
<default>
  <joint damping=".005" actuatorfrcrange="-1000 1000"/> <!-- Reduced damping, increased actuatorfrcrange -->
  <default class="wheel">
    <geom type="cylinder" size=".2 .05" rgba=".5 .5 1 1" friction="0.01"/> <!-- Adjusted wheel size and friction -->
  </default>
  <default class="decor">
    <site type="box" rgba=".5 1 .5 1"/>
  </default>
</default>


    
    <worldbody>
        <!-- Define the floor -->
        <body name="floor" pos="10 10 0">
            <geom name="floor_geom" type="plane" size="50 50 1" rgba="0.5 0.5 0.5 1"/>
        </body>
        <body name="obstacles">
            <!-- Define obstacles in a 10x10 grid pattern with 1x1 spacing -->
            <!-- Row 1 -->
            <geom name="obstacle_0_0" type="box" size="0.5 23 1" pos="-15 7 0.25" rgba="0.8 0 0 1"/>
            <geom name="obstacle_0_1" type="box" size="10 0.5 1" pos="-5 -10 0.25" rgba="0.8 0 0 1"/>
            <geom name="obstacle_0_2" type="box" size="0.5 0.5 1" pos="-15 -5 0.25" rgba="0.8 0 0 1"/>
            <geom name="obstacle_0_3" type="box" size="0.5 0.5 1" pos="-15 0 0.25" rgba="0.8 0 0 1"/>
            <geom name="obstacle_0_4" type="box" size="0.5 0.5 1" pos="-15 5 0.25" rgba="0.8 0 0 1"/>
            <geom name="obstacle_0_5" type="box" size="0.5 0.5 1" pos="-15 10 0.25" rgba="0.8 0 0 1"/>
            <geom name="obstacle_0_6" type="box" size="0.5 0.5 1" pos="-15 15 0.25" rgba="0.8 0 0 1"/>
            <geom name="obstacle_0_7" type="box" size="0.5 0.5 1" pos="-15 20 0.25" rgba="0.8 0 0 1"/>
            <geom name="obstacle_0_8" type="box" size="0.5 0.5 1" pos="-15 25 0.25" rgba="0.8 0 0 1"/>
            <geom name="obstacle_0_9" type="box" size="23 0.5 1" pos="7 30 0.25" rgba="0.8 0 0 1"/>

            <!-- Row 2 -->
            <geom name="obstacle_1_0" type="box" size="0.5 10 1" pos="-10 0 0.25" rgba="0.8 0 0 1"/>
            <geom name="obstacle_1_1" type="box" size="0.5 0.5 1" pos="-10 -10 0.25" rgba="0.8 0 0 1"/>
            <geom name="obstacle_1_2" type="box" size="0.5 0.5 1" pos="-10 -5 0.25" rgba="0.8 0 0 1"/>
            <geom name="obstacle_1_3" type="box" size="0.5 0.5 1" pos="-10 0 0.25" rgba="0.8 0 0 1"/>
            <geom name="obstacle_1_4" type="box" size="0.5 0.5 1" pos="-10 5 0.25" rgba="0.8 0 0 1"/>
            <geom name="obstacle_1_5" type="box" size="0.5 0.5 1" pos="-10 10 0.25" rgba="0.8 0 0 1"/>
            <geom name="obstacle_1_6" type="box" size="0.5 0.5 1" pos="-10 15 0.25" rgba="0.8 0 0 1"/>
            <geom name="obstacle_1_7" type="box" size="0.5 0.5 1" pos="-10 20 0.25" rgba="0.8 0 0 1"/>
            <geom name="obstacle_1_8" type="box" size="0.5 0.5 1" pos="-10 25 0.25" rgba="0.8 0 0 1"/>
            <geom name="obstacle_1_9" type="box" size="0.5 5 1" pos="-10 20 0.25" rgba="0.8 0 0 1"/>

            <!-- Row 3 -->
            <geom name="obstacle_2_0" type="box" size="0.5 15 1" pos="-5 10 0.25" rgba="0.8 0 0 1"/>
            <geom name="obstacle_2_1" type="box" size="0.5 0.5 1" pos="-5 -10 0.25" rgba="0.8 0 0 1"/>
            <geom name="obstacle_2_2" type="box" size="0.5 0.5 1" pos="-5 -5 0.25" rgba="0.8 0 0 1"/>
            <geom name="obstacle_2_3" type="box" size="0.5 0.5 1" pos="-5 0 0.25" rgba="0.8 0 0 1"/>
            <geom name="obstacle_2_4" type="box" size="0.5 0.5 1" pos="-5 5 0.25" rgba="0.8 0 0 1"/>
            <geom name="obstacle_2_5" type="box" size="0.5 0.5 1" pos="-5 10 0.25" rgba="0.8 0 0 1"/>
            <geom name="obstacle_2_6" type="box" size="0.5 0.5 1" pos="-5 15 0.25" rgba="0.8 0 0 1"/>
            <geom name="obstacle_2_7" type="box" size="0.5 0.5 1" pos="-5 20 0.25" rgba="0.8 0 0 1"/>
            <geom name="obstacle_2_8" type="box" size="0.5 0.5 1" pos="-5 25 0.25" rgba="0.8 0 0 1"/>
            <geom name="obstacle_2_9" type="box" size="0.5 0.5 1" pos="-5 30 0.25" rgba="0.8 0 0 1"/>

            <!-- Row 4 -->
            <geom name="obstacle_3_0" type="box" size="0.5 10 1" pos="0 0 0.25" rgba="0.8 0 0 1"/>
            <geom name="obstacle_3_1" type="box" size="0.5 0.5 1" pos="0 -10 0.25" rgba="0.8 0 0 1"/>
            <geom name="obstacle_3_2" type="box" size="0.5 0.5 1" pos="0 -5 0.25" rgba="0.8 0 0 1"/>
            <geom name="obstacle_3_3" type="box" size="0.5 0.5 1" pos="0 0 0.25" rgba="0.8 0 0 1"/>
            <geom name="obstacle_3_4" type="box" size="0.5 0.5 1" pos="0 5 0.25" rgba="0.8 0 0 1"/>
            <geom name="obstacle_3_5" type="box" size="0.5 0.5 1" pos="0 10 0.25" rgba="0.8 0 0 1"/>
            <geom name="obstacle_3_6" type="box" size="0.5 0.5 1" pos="0 15 0.25" rgba="0.8 0 0 1"/>
            <geom name="obstacle_3_7" type="box" size="0.5 0.5 1" pos="0 20 0.25" rgba="0.8 0 0 1"/>
            <geom name="obstacle_3_8" type="box" size="0.5 0.5 1" pos="0 25 0.25" rgba="0.8 0 0 1"/>
            <geom name="obstacle_3_9" type="box" size="0.5 0.5 1" pos="0 30 0.25" rgba="0.8 0 0 1"/>

            <!-- Row 5 -->
            <geom name="obstacle_4_0" type="box" size="0.5 10 1" pos="5 0 0.25" rgba="0.8 0 0 1"/>
            <geom name="obstacle_4_1" type="box" size="0.5 0.5 1" pos="5 -10 0.25" rgba="0.8 0 0 1"/>
            <geom name="obstacle_4_2" type="box" size="0.5 0.5 1" pos="5 -5 0.25" rgba="0.8 0 0 1"/>
            <geom name="obstacle_4_3" type="box" size="0.5 0.5 1" pos="5 0 0.25" rgba="0.8 0 0 1"/>
            <geom name="obstacle_4_4" type="box" size="0.5 0.5 1" pos="5 5 0.25" rgba="0.8 0 0 1"/>
            <geom name="obstacle_4_5" type="box" size="0.5 0.5 1" pos="5 10 0.25" rgba="0.8 0 0 1"/>
            <geom name="obstacle_4_6" type="box" size="0.5 0.5 1" pos="5 15 0.25" rgba="0.8 0 0 1"/>
            <geom name="obstacle_4_7" type="box" size="0.5 0.5 1" pos="5 20 0.25" rgba="0.8 0 0 1"/>
            <geom name="obstacle_4_8" type="box" size="0.5 0.5 1" pos="5 25 0.25" rgba="0.8 0 0 1"/>
            <geom name="obstacle_4_9" type="box" size="0.5 0.5 1" pos="5 30 0.25" rgba="0.8 0 0 1"/>

            <!-- Row 6 -->
            <geom name="obstacle_5_0" type="box" size="0.5 10 1" pos="10 0 0.25" rgba="0.8 0 0 1"/>
            <geom name="obstacle_5_1" type="box" size="0.5 0.5 1" pos="10 -10 0.25" rgba="0.8 0 0 1"/>
            <geom name="obstacle_5_2" type="box" size="0.5 0.5 1" pos="10 -5 0.25" rgba="0.8 0 0 1"/>
            <geom name="obstacle_5_3" type="box" size="0.5 0.5 1" pos="10 0 0.25" rgba="0.8 0 0 1"/>
            <geom name="obstacle_5_4" type="box" size="0.5 0.5 1" pos="10 5 0.25" rgba="0.8 0 0 1"/>
            <geom name="obstacle_5_5" type="box" size="0.5 0.5 1" pos="10 10 0.25" rgba="0.8 0 0 1"/>
            <geom name="obstacle_5_6" type="box" size="0.5 0.5 1" pos="10 15 0.25" rgba="0.8 0 0 1"/>
            <geom name="obstacle_5_7" type="box" size="0.5 0.5 1" pos="10 20 0.25" rgba="0.8 0 0 1"/>
            <geom name="obstacle_5_8" type="box" size="0.5 0.5 1" pos="10 25 0.25" rgba="0.8 0 0 1"/>
            <geom name="obstacle_5_9" type="box" size="0.5 0.5 1" pos="10 30 0.25" rgba="0.8 0 0 1"/>

            <!-- Row 7 -->
            <geom name="obstacle_6_0" type="box" size="0.5 10 1" pos="15 0 0.25" rgba="0.8 0 0 1"/>
            <geom name="obstacle_6_1" type="box" size="0.5 0.5 1" pos="15 -10 0.25" rgba="0.8 0 0 1"/>
            <geom name="obstacle_6_2" type="box" size="0.5 0.5 1" pos="15 -5 0.25" rgba="0.8 0 0 1"/>
            <geom name="obstacle_6_3" type="box" size="0.5 0.5 1" pos="15 0 0.25" rgba="0.8 0 0 1"/>
            <geom name="obstacle_6_4" type="box" size="0.5 0.5 1" pos="15 5 0.25" rgba="0.8 0 0 1"/>
            <geom name="obstacle_6_5" type="box" size="0.5 0.5 1" pos="15 10 0.25" rgba="0.8 0 0 1"/>
            <geom name="obstacle_6_6" type="box" size="0.5 0.5 1" pos="15 15 0.25" rgba="0.8 0 0 1"/>
            <geom name="obstacle_6_7" type="box" size="0.5 0.5 1" pos="15 20 0.25" rgba="0.8 0 0 1"/>
            <geom name="obstacle_6_8" type="box" size="0.5 0.5 1" pos="15 25 0.25" rgba="0.8 0 0 1"/>
            <geom name="obstacle_6_9" type="box" size="0.5 0.5 1" pos="15 30 0.25" rgba="0.8 0 0 1"/>

            <!-- Row 8 -->
            <geom name="obstacle_7_1" type="box" size="0.5 15 1" pos="20 5 0.25" rgba="0.8 0 0 1"/>
            <geom name="obstacle_7_0" type="box" size="0.5 0.5 1" pos="20 -15 0.25" rgba="0.8 0 0 1"/>
            <geom name="obstacle_7_2" type="box" size="0.5 0.5 1" pos="20 -5 0.25" rgba="0.8 0 0 1"/>
            <geom name="obstacle_7_3" type="box" size="0.5 0.5 1" pos="20 0 0.25" rgba="0.8 0 0 1"/>
            <geom name="obstacle_7_4" type="box" size="0.5 0.5 1" pos="20 5 0.25" rgba="0.8 0 0 1"/>
            <geom name="obstacle_7_5" type="box" size="0.5 0.5 1" pos="20 10 0.25" rgba="0.8 0 0 1"/>
            <geom name="obstacle_7_6" type="box" size="0.5 0.5 1" pos="20 15 0.25" rgba="0.8 0 0 1"/>
            <geom name="obstacle_7_7" type="box" size="0.5 0.5 1" pos="20 20 0.25" rgba="0.8 0 0 1"/>
            <geom name="obstacle_7_8" type="box" size="0.5 0.5 1" pos="20 25 0.25" rgba="0.8 0 0 1"/>
            <geom name="obstacle_7_9" type="box" size="0.5 0.5 1" pos="20 30 0.25" rgba="0.8 0 0 1"/>

            <!-- Row 9 -->
            <geom name="obstacle_8_0" type="box" size="0.5 15 1" pos="25 10 0.25" rgba="0.8 0 0 1"/>
            <geom name="obstacle_8_1" type="box" size="0.5 0.5 1" pos="25 -10 0.25" rgba="0.8 0 0 1"/>
            <geom name="obstacle_8_2" type="box" size="0.5 0.5 1" pos="25 -5 0.25" rgba="0.8 0 0 1"/>
            <geom name="obstacle_8_3" type="box" size="0.5 0.5 1" pos="25 0 0.25" rgba="0.8 0 0 1"/>
            <geom name="obstacle_8_4" type="box" size="0.5 0.5 1" pos="25 5 0.25" rgba="0.8 0 0 1"/>
            <geom name="obstacle_8_5" type="box" size="0.5 0.5 1" pos="25 10 0.25" rgba="0.8 0 0 1"/>
            <geom name="obstacle_8_6" type="box" size="0.5 0.5 1" pos="25 15 0.25" rgba="0.8 0 0 1"/>
            <geom name="obstacle_8_7" type="box" size="0.5 0.5 1" pos="25 20 0.25" rgba="0.8 0 0 1"/>
            <geom name="obstacle_8_8" type="box" size="0.5 0.5 1" pos="25 25 0.25" rgba="0.8 0 0 1"/>
            <geom name="obstacle_8_9" type="box" size="0.5 0.5 1" pos="25 30 0.25" rgba="0.8 0 0 1"/>

            <!-- Row 10 -->
            <geom name="obstacle_9_0" type="box" size="23 0.5 1" pos="7 -15 0.25" rgba="0.8 0 0 1"/>
            <geom name="obstacle_9_1" type="box" size="0.5 0.5 1" pos="30 -10 0.25" rgba="0.8 0 0 1"/>
            <geom name="obstacle_9_2" type="box" size="0.5 0.5 1" pos="30 -5 0.25" rgba="0.8 0 0 1"/>
            <geom name="obstacle_9_3" type="box" size="0.5 0.5 1" pos="30 0 0.25" rgba="0.8 0 0 1"/>
            <geom name="obstacle_9_4" type="box" size="0.5 0.5 1" pos="30 5 0.25" rgba="0.8 0 0 1"/>
            <geom name="obstacle_9_5" type="box" size="0.5 0.5 1" pos="30 10 0.25" rgba="0.8 0 0 1"/>
            <geom name="obstacle_9_6" type="box" size="10 0.5 1" pos="10 15 0.25" rgba="0.8 0 0 1"/>
            <geom name="obstacle_9_7" type="box" size="5 0.5 1" pos="10 20 0.25" rgba="0.8 0 0 1"/>
            <geom name="obstacle_9_8" type="box" size="10 0.5 1" pos="10 25 0.25" rgba="0.8 0 0 1"/>
            <geom name="obstacle_9_9" type="box" size="0.5 23 1" pos="30 7 0.25" rgba="0.8 0 0 1"/>
        </body>

<!-- Define the agent -->
<body name="car" pos="-12 -13 0.5">
      <freejoint/>
      <light name="top light" pos="0 0 2" mode="trackcom" diffuse=".4 .4 .4"/>
      <geom name="chasis" type="mesh" mesh="chasis"/>
      <geom name="front wheel" pos=".8 0 -.15" type="sphere" size=".15" condim="1" priority="1"/>
      <light name="front light" pos="1 0 .2" dir="2 0 -1" diffuse="1 1 1"/>
      <body name="left wheel" pos="-.7 .6 0" zaxis="0 1 0">
        <joint name="left"/>
        <geom class="wheel"/>
        <site class="decor" size=".06 .25 .12"/>
        <site class="decor" size=".25 .06 .12"/>
      </body>
      <body name="right wheel" pos="-.7 -.6 0" zaxis="0 1 0">
        <joint name="right"/>
        <geom class="wheel"/>
        <site class="decor" size=".06 .25 .12"/>
        <site class="decor" size=".25 .06 .12"/>
      </body>
    </body>


               



<!-- Define the destination -->
<body name="destination" pos="27 27 0.5">
    <!-- Base of the robot -->
    <geom name="destination_base" type="cylinder" size="0.5 0.5" pos="0 0 0.3" rgba="0.8 0.8 0.8 1"/>
    
    <!-- Body of the robot -->
    <geom name="destination_body" type="box" size="0.35 0.35 0.5" pos="0 0 0.65" rgba="0.9 0.6 0.6 1"/>
    
    <!-- Head of the robot -->
    <geom name="destination_head" type="sphere" size="0.25" pos="0 0 1.1" rgba="0.9 0.6 0.6 1"/>
    
    <!-- Eyes of the robot -->
    <geom name="destination_left_eye" type="sphere" size="0.05" pos="-0.1 0.1 1.2" rgba="0.1 0.1 0.1 1"/>
    <geom name="destination_right_eye" type="sphere" size="0.05" pos="0.1 0.1 1.2" rgba="0.1 0.1 0.1 1"/>
    
    <!-- Eyebrows -->
    <geom name="destination_left_eyebrow" type="box" size="0.07 0.02 0.01" pos="-0.1 0.13 1.25" rgba="0.2 0.1 0.1 1"/>
    <geom name="destination_right_eyebrow" type="box" size="0.07 0.02 0.01" pos="0.1 0.13 1.25" rgba="0.2 0.1 0.1 1"/>
    
    <!-- Mouth -->
    <geom name="destination_mouth" type="box" size="0.1 0.02 0.01" pos="0 0.1 1.05" rgba="0.2 0.1 0.1 1"/>
    
    <!-- Hair (simple box as a placeholder for hair) -->
    <geom name="destination_hair" type="box" size="0.3 0.1 0.1" pos="0 0 1.3" rgba="0.3 0.1 0.1 1"/>
    
    <!-- Left arm -->
    <geom name="destination_left_arm" type="box" size="0.1 0.35 0.1" pos="-0.45 0 0.7" rgba="0.9 0.6 0.6 1"/>
    
    <!-- Right arm -->
    <geom name="destination_right_arm" type="box" size="0.1 0.35 0.1" pos="0.45 0 0.7" rgba="0.9 0.6 0.6 1"/>
    
    <!-- Left hand -->
    <geom name="destination_left_hand" type="box" size="0.05 0.05 0.02" pos="-0.45 0 0.35" rgba="0.9 0.6 0.6 1"/>
    
    <!-- Right hand -->
    <geom name="destination_right_hand" type="box" size="0.05 0.05 0.02" pos="0.45 0 0.35" rgba="0.9 0.6 0.6 1"/>
    
    <!-- Left leg -->
    <geom name="destination_left_leg" type="box" size="0.1 0.1 0.4" pos="-0.2 0 -0.4" rgba="0.9 0.6 0.6 1"/>
    
    <!-- Right leg -->
    <geom name="destination_right_leg" type="box" size="0.1 0.1 0.4" pos="0.2 0 -0.4" rgba="0.9 0.6 0.6 1"/>
    
    <!-- Left foot -->
    <geom name="destination_left_foot" type="box" size="0.1 0.05 0.02" pos="-0.2 0 -0.55" rgba="0.9 0.6 0.6 1"/>
    
    <!-- Right foot -->
    <geom name="destination_right_foot" type="box" size="0.1 0.05 0.02" pos="0.2 0 -0.55" rgba="0.9 0.6 0.6 1"/>
    
    <!-- Additional features -->
    <!-- Nose -->
    <geom name="destination_nose" type="sphere" size="0.05" pos="0 0.1 1.1" rgba="0.9 0.6 0.6 1"/>
    
    <!-- Decorative elements -->
    <geom name="destination_decoration" type="box" size="0.05 0.05 0.02" pos="0 0.15 1.2" rgba="1 0.5 0.5 1"/>
</body>
    </worldbody>

<tendon>
    <fixed name="forward">
        <joint joint="left" coef="200.0"/>  <!-- Increased coefficient -->
        <joint joint="right" coef="200.0"/> <!-- Increased coefficient -->
    </fixed>
    <fixed name="turn">
        <joint joint="left" coef="-2.0"/> <!-- Increased coefficient -->
        <joint joint="right" coef="2.0"/>  <!-- Increased coefficient -->
    </fixed>
</tendon>


<actuator>
    <motor name="forward" tendon="forward" ctrlrange="-10 10"/> <!-- Increased from -2 2 to -10 10 -->
    <motor name="turn" tendon="turn" ctrlrange="-10 10"/> <!-- Increased from -2 2 to -10 10 -->
</actuator>


  <sensor>
    <jointactuatorfrc name="right" joint="right"/>
    <jointactuatorfrc name="left" joint="left"/>
  </sensor>



    
</mujoco>
